<?xml version ='1.0'?>
<sdf version ='1.4'>
  <world name='default'>
    <physics type='ode'>
      <max_step_size>0.001</max_step_size>
      <real_time_factor>1</real_time_factor>
      <real_time_update_rate>1000</real_time_update_rate>
      <gravity>0 0 0</gravity>
    </physics>

    <include>
      <uri>model://sun</uri>
    </include>

    <scene>
      <background>0.079 .285 .940 1</background>
      <shadows>0</shadows>
      <fog>
		<color>0.079 .285 .940 1</color>
		<type>linear</type>
		<start>1</start>
		<end>100</end>
		<density>50</density>
      </fog>
    </scene>

    <model name="my_robot">
      <plugin name="robot" filename="librobot.so"></plugin>
      <static>false</static>
      <pose>3 -3.5 2 0 0 3.14</pose>
      <link name='body'>

	<collision name='collision'>
	  <geometry>
	    <mesh>
	      <uri>file://../models/RobotColorGazebo.dae</uri>
	      <scale> .008 .008 .008</scale>
	    </mesh>
	  </geometry>
	</collision>

	<visual name='visual'>
	  <geometry>
	    <mesh>
	      <uri>file://../models/RobotColorGazebo.dae</uri>
	      <scale> .008 .008 .008</scale>
	    </mesh>
	  </geometry>
	</visual>

      </link>
	<!-- camera pointing forward -->
      <joint name='camera_robot' type='revolute'>
		<parent>body</parent>
		<child>camera_link</child>
		<axis>1 0 0</axis>
		<pose>0 0 0 0 0 0</pose>
      </joint>

      <link name='camera_link'>
	<pose>0 0 0 0 0 -1.507</pose>

	<collision name='collision'>
	  <geometry>
	    <box>
	      <size>.03 .03 .03</size>
	    </box>
	  </geometry>
	</collision>

	<visual name='visual'>
	  <geometry>
	    <box>
	      <size>.03 .03 .03</size>
	    </box>
	  </geometry>
	</visual>

	<sensor type="camera" name="camera1">
	  <update_rate>300.0</update_rate>

	  <camera name="head">
	    <horizontal_fov>1.3962634</horizontal_fov>
	    <image>
	      <width>800</width>
	      <height>800</height>
	      <format>R8G8B8</format>
	    </image>
	    <clip>
	      <near>0.02</near>
	      <far>300</far>
	    </clip>
	    <noise>
	      <type>gaussian</type>-->
	      <mean>0.0</mean>
	      <stddev>0.007</stddev>
	    </noise>
	  </camera>

	  <plugin name="camera_controller" filename="libgazebo_ros_camera.so">
	    <alwaysOn>true</alwaysOn>
	    <updateRate>0.0</updateRate>
	    <cameraName>my_robot/camera1</cameraName>
	    <imageTopicName>image_raw</imageTopicName>
	    <cameraInfoTopicName>camera_info</cameraInfoTopicName>
	    <frameName>camera_link</frameName>
	    <hackBaseline>0.07</hackBaseline>
	    <distortionK1>0.0</distortionK1>
	    <distortionK2>0.0</distortionK2>
	    <distortionK3>0.0</distortionK3>
	    <distortionT1>0.0</distortionT1>
	    <distortionT2>0.0</distortionT2>
	  </plugin>

	</sensor>
      </link>
      
    <!-- Camera pointing forward done -->

	<!-- camera pointing downwards -->
      <joint name='camera_robot_down' type='revolute'>
		<parent>body</parent>
		<child>camera_link_down</child>
		<axis>1 0 0</axis>
		<pose>0 0 0 0 0 0</pose>
      </joint>

      <link name='camera_link_down'>
	<pose>0 .2 -.2 0 1.5 0</pose>

	<collision name='collision'>
	  <geometry>
	    <box>
	      <size>.03 .03 .03</size>
	    </box>
	  </geometry>
	</collision>

	<visual name='visual'>
	  <geometry>
	    <box>
	      <size>.03 .03 .03</size>
	    </box>
	  </geometry>
	</visual>

	<sensor type="camera" name="camera_down">
	  <update_rate>300.0</update_rate>

	  <camera name="head">
	    <horizontal_fov>1.3962634</horizontal_fov>
	    <image>
	      <width>800</width>
	      <height>800</height>
	      <format>R8G8B8</format>
	    </image>
	    <clip>
	      <near>0.02</near>
	      <far>300</far>
	    </clip>
	    <noise>
	      <type>gaussian</type>-->
	      <mean>0.0</mean>
	      <stddev>0.007</stddev>
	    </noise>
	  </camera>

	  <plugin name="camera_controller" filename="libgazebo_ros_camera.so">
	    <alwaysOn>true</alwaysOn>
	    <updateRate>0.0</updateRate>
	    <cameraName>my_robot/camera_down</cameraName>
	    <imageTopicName>image_raw</imageTopicName>
	    <cameraInfoTopicName>camera_info</cameraInfoTopicName>
	    <frameName>camera_link</frameName>
	    <hackBaseline>0.07</hackBaseline>
	    <distortionK1>0.0</distortionK1>
	    <distortionK2>0.0</distortionK2>
	    <distortionK3>0.0</distortionK3>
	    <distortionT1>0.0</distortionT1>
	    <distortionT2>0.0</distortionT2>
	  </plugin>

	</sensor>
      </link>
      <!-- Camera pointing downwards done -->

    </model>

	<!-- bin 1 -->
    <model name="bin1">
      <pose>3 -3.5 0 0 0 0</pose>
      <static>false</static>
      <link name="body">
      
        <collision name="visual">
          <geometry>
            <mesh>
	      <uri>file://../models/BinColor1.dae</uri>
	      <scale> .01 .01 .01</scale>
	    </mesh>
          </geometry>
        </collision>
      
        <visual name="visual">
          <geometry>
            <mesh>
	      <uri>file://../models/BinColor1.dae</uri>
	      <scale> .01 .01 .01</scale>
	    </mesh>
          </geometry>
        </visual>
        
      </link>

      <joint name='bin1_image1' type='revolute'>
		<parent>body</parent>
		<child>image</child>
		<axis>1 0 0</axis>
		<pose>0 0 0 0 0 0</pose>
      </joint>

      
      <link name="image">
		<pose>0 0 0.05 0 0 0</pose>
      
        <visual name="visual">
          <geometry>
            <mesh>
	      <uri>file://../models/RoboSub37.dae</uri>
	      <scale> .03 .025 .01</scale>
	    </mesh>
          </geometry>
        </visual>
      </link>

    </model>
	<!-- bin 1 done -->
	
	<!-- bin 2 -->
    <model name="bin2">
      <pose>3 -1.5 0 0 0 0</pose>
      <static>false</static>
      <link name="body">
      
        <collision name="visual">
          <geometry>
            <mesh>
	      <uri>file://../models/BinColor1.dae</uri>
	      <scale> .01 .01 .01</scale>
	    </mesh>
          </geometry>
        </collision>
      
        <visual name="visual">
          <geometry>
            <mesh>
	      <uri>file://../models/BinColor1.dae</uri>
	      <scale> .01 .01 .01</scale>
	    </mesh>
          </geometry>
        </visual>
        
      </link>

      <joint name='bin2_image' type='revolute'>
		<parent>body</parent>
		<child>image</child>
		<axis>1 0 0</axis>
		<pose>0 0 0 0 0 0</pose>
      </joint>

      
      <link name="image">
		<pose>0 0 0.05 0 0 0</pose>
      
        <visual name="visual">
          <geometry>
            <mesh>
	      <uri>file://../models/RoboSub10.dae</uri>
	      <scale> .03 .025 .01</scale>
	    </mesh>
          </geometry>
        </visual>
      </link>

    </model>
	<!-- bin 2 done -->
	
	<!-- bin 3 -->
    <model name="bin3">
      <pose>3 .5 0 0 0 0</pose>
      <static>false</static>
      <link name="body">
      
        <collision name="visual">
          <geometry>
            <mesh>
	      <uri>file://../models/BinColor1.dae</uri>
	      <scale> .01 .01 .01</scale>
	    </mesh>
          </geometry>
        </collision>
      
        <visual name="visual">
          <geometry>
            <mesh>
	      <uri>file://../models/BinColor1.dae</uri>
	      <scale> .01 .01 .01</scale>
	    </mesh>
          </geometry>
        </visual>
        
      </link>

      <joint name='bin3_image' type='revolute'>
		<parent>body</parent>
		<child>image</child>
		<axis>1 0 0</axis>
		<pose>0 0 0 0 0 0</pose>
      </joint>

      
      <link name="image">
		<pose>0 0 0.05 0 0 0</pose>
      
        <visual name="visual">
          <geometry>
            <mesh>
	      <uri>file://../models/RoboSub98.dae</uri>
	      <scale> .03 .025 .01</scale>
	    </mesh>
          </geometry>
        </visual>
      </link>

    </model>
    <!-- bin 3 done -->
    
    <!-- bin 4 -->
    <model name="bin4">
      <pose>3 2.5 0 0 0 0</pose>
      <static>false</static>
      <link name="body">
      
        <collision name="visual">
          <geometry>
            <mesh>
	      <uri>file://../models/BinColor1.dae</uri>
	      <scale> .01 .01 .01</scale>
	    </mesh>
          </geometry>
        </collision>
      
        <visual name="visual">
          <geometry>
            <mesh>
	      <uri>file://../models/BinColor1.dae</uri>
	      <scale> .01 .01 .01</scale>
	    </mesh>
          </geometry>
        </visual>
        
      </link>

      <joint name='bin4_image' type='revolute'>
		<parent>body</parent>
		<child>image</child>
		<axis>1 0 0</axis>
		<pose>0 0 0 0 0 0</pose>
      </joint>

      
      <link name="image">
		<pose>0 0 0.05 0 0 -1.5707963</pose>
      
        <visual name="visual">
          <geometry>
            <mesh>
	      <uri>file://../models/RoboSub16.dae</uri>
	      <scale> .03 .025 .01</scale>
	    </mesh>
          </geometry>
        </visual>
      </link>

    </model>
    <!-- bin 4 done -->
  </world>
</sdf>
